Workbook

Sheet Dashboard
A1: Food Delivery: KPI Dashboard
A2: Synthetic data, 300 orders, 14 days. Gap = result minus target. Inputs are on the Assumptions sheet.
A4: 1. Headline KPIs
A5: KPI | B5: Dataset result | C5: Business case baseline | D5: Target | E5: Gap to target
A6: Total orders | B6: =COUNTA(Data!$A$2:$A$301) -> 300
A7: Delivered orders | B7: =COUNTIF(Data!$F$2:$F$301,"Delivered") -> 267
A8: Cancelled orders | B8: =COUNTIF(Data!$F$2:$F$301,"Cancelled") -> 33
A9: Cancellation rate (G2) | B9: =B8/B6 -> 0.11 | C9: =Assumptions!B13 -> 0.11 | D9: =Assumptions!B10 -> 0.07 | E9: =B9-D9 -> 0.04
A10: Avg delivery time, min (G1) | B10: =AVERAGEIFS(Data!$N$2:$N$301,Data!$F$2:$F$301,"Delivered") -> 40.925094 | C10: =Assumptions!B12 -> 41 | D10: =Assumptions!B9 -> 34 | E10: =B10-D10 -> 6.9250936
A11: Avg customer rating (G3) | B11: =AVERAGE(Data!$O$2:$O$301) -> 4.0973783 | C11: =Assumptions!B14 -> 4.1 | D11: =Assumptions!B11 -> 4.4 | E11: =B11-D11 -> -0.30262172
A12: SLA breach rate (delivered orders) | B12: =COUNTIF(Data!$Q$2:$Q$301,"Yes")/B7 -> 0.30337079
A14: 2. Peak vs off-peak
A15: Metric | B15: Peak | C15: Off-peak | D15: Difference (peak - off-peak)
A16: Orders | B16: =COUNTIF(Data!$D$2:$D$301,B$15) -> 134 | C16: =COUNTIF(Data!$D$2:$D$301,C$15) -> 166 | D16: =B16-C16 -> -32
A17: Cancelled orders | B17: =COUNTIFS(Data!$D$2:$D$301,B$15,Data!$F$2:$F$301,"Cancelled") -> 21 | C17: =COUNTIFS(Data!$D$2:$D$301,C$15,Data!$F$2:$F$301,"Cancelled") -> 12 | D17: =B17-C17 -> 9
A18: Cancellation rate | B18: =IFERROR(B17/B16,0) -> 0.15671642 | C18: =IFERROR(C17/C16,0) -> 0.072289157 | D18: =B18-C18 -> 0.084427261
A19: Avg delivery time (min) | B19: =AVERAGEIFS(Data!$N$2:$N$301,Data!$D$2:$D$301,B$15,Data!$F$2:$F$301,"Delivered") -> 49.327434 | C19: =AVERAGEIFS(Data!$N$2:$N$301,Data!$D$2:$D$301,C$15,Data!$F$2:$F$301,"Delivered") -> 34.75974 | D19: =B19-C19 -> 14.567693
A20: Avg customer rating | B20: =AVERAGEIFS(Data!$O$2:$O$301,Data!$D$2:$D$301,B$15) -> 3.6460177 | C20: =AVERAGEIFS(Data!$O$2:$O$301,Data!$D$2:$D$301,C$15) -> 4.4285714 | D20: =B20-C20 -> -0.78255373
A21: SLA breach rate | B21: =IFERROR(COUNTIFS(Data!$D$2:$D$301,B$15,Data!$Q$2:$Q$301,"Yes")/COUNTIFS(Data!$D$2:$D$301,B$15,Data!$F$2:$F$301,"Delivered"),0) -> 0.60176991 | C21: =IFERROR(COUNTIFS(Data!$D$2:$D$301,C$15,Data!$Q$2:$Q$301,"Yes")/COUNTIFS(Data!$D$2:$D$301,C$15,Data!$F$2:$F$301,"Delivered"),0) -> 0.084415584 | D21: =B21-C21 -> 0.51735433
A24: 3. Average stage duration, delivered orders (min)
A25: Stage | B25: Peak | C25: Off-peak | D25: Difference | E25: Share of total difference | F25: Related bottleneck
A26: Confirmation | B26: =AVERAGEIFS(Data!$H$2:$H$301,Data!$D$2:$D$301,B$25,Data!$F$2:$F$301,"Delivered") -> 4.0265487 | C26: =AVERAGEIFS(Data!$H$2:$H$301,Data!$D$2:$D$301,C$25,Data!$F$2:$F$301,"Delivered") -> 1.8961039 | D26: =B26-C26 -> 2.1304448 | E26: =IFERROR(D26/D$32,0) -> 0.14624448 | F26: B1: no confirmation timer
A27: Preparation | B27: =AVERAGEIFS(Data!$I$2:$I$301,Data!$D$2:$D$301,B$25,Data!$F$2:$F$301,"Delivered") -> 15.115044 | C27: =AVERAGEIFS(Data!$I$2:$I$301,Data!$D$2:$D$301,C$25,Data!$F$2:$F$301,"Delivered") -> 12.584416 | D27: =B27-C27 -> 2.5306287 | E27: =IFERROR(D27/D$32,0) -> 0.17371512 | F27: Restaurant load at peak hours
A28: Courier assignment | B28: =AVERAGEIFS(Data!$J$2:$J$301,Data!$D$2:$D$301,B$25,Data!$F$2:$F$301,"Delivered") -> 7.0353982 | C28: =AVERAGEIFS(Data!$J$2:$J$301,Data!$D$2:$D$301,C$25,Data!$F$2:$F$301,"Delivered") -> 3.5454545 | D28: =B28-C28 -> 3.4899437 | E28: =IFERROR(D28/D$32,0) -> 0.23956735 | F28: B3: manual courier assignment
A29: Travel to restaurant | B29: =AVERAGEIFS(Data!$K$2:$K$301,Data!$D$2:$D$301,B$25,Data!$F$2:$F$301,"Delivered") -> 7.7168142 | C29: =AVERAGEIFS(Data!$K$2:$K$301,Data!$D$2:$D$301,C$25,Data!$F$2:$F$301,"Delivered") -> 6.038961 | D29: =B29-C29 -> 1.6778531 | E29: =IFERROR(D29/D$32,0) -> 0.11517631 | F29: Traffic and distance
A30: Wait at restaurant | B30: =AVERAGEIFS(Data!$L$2:$L$301,Data!$D$2:$D$301,B$25,Data!$F$2:$F$301,"Delivered") -> 5.1061947 | C30: =AVERAGEIFS(Data!$L$2:$L$301,Data!$D$2:$D$301,C$25,Data!$F$2:$F$301,"Delivered") -> 1.8311688 | D30: =B30-C30 -> 3.2750259 | E30: =IFERROR(D30/D$32,0) -> 0.2248143 | F30: B2: prep time not shared with couriers
A31: Travel to customer | B31: =AVERAGEIFS(Data!$M$2:$M$301,Data!$D$2:$D$301,B$25,Data!$F$2:$F$301,"Delivered") -> 10.327434 | C31: =AVERAGEIFS(Data!$M$2:$M$301,Data!$D$2:$D$301,C$25,Data!$F$2:$F$301,"Delivered") -> 8.8636364 | D31: =B31-C31 -> 1.4637973 | E31: =IFERROR(D31/D$32,0) -> 0.10048243 | F31: Traffic and distance
A32: Total delivery time | B32: =SUM(B26:B31) -> 49.327434 | C32: =SUM(C26:C31) -> 34.75974 | D32: =SUM(D26:D31) -> 14.567693 | E32: =SUM(E26:E31) -> 1
A35: 4. Cancellation reasons
A36: Reason | B36: Orders | C36: Share | D36: Related bottleneck
A37: Restaurant did not confirm | B37: =COUNTIF(Data!$G$2:$G$301,A37) -> 11 | C37: =IFERROR(B37/B$41,0) -> 0.33333333 | D37: B1: no confirmation timer
A38: Courier not assigned in time | B38: =COUNTIF(Data!$G$2:$G$301,A38) -> 10 | C38: =IFERROR(B38/B$41,0) -> 0.3030303 | D38: B3: manual courier assignment
A39: Customer cancelled: long wait | B39: =COUNTIF(Data!$G$2:$G$301,A39) -> 9 | C39: =IFERROR(B39/B$41,0) -> 0.27272727 | D39: B4: no status updates for customer
A40: Item unavailable | B40: =COUNTIF(Data!$G$2:$G$301,A40) -> 3 | C40: =IFERROR(B40/B$41,0) -> 0.090909091 | D40: Menu availability (US-06)
A41: Total | B41: =SUM(B37:B40) -> 33 | C41: =SUM(C37:C40) -> 1
A44: 5. Performance by order hour
A45: Order hour | B45: Orders | C45: Cancelled | D45: Cancellation rate | E45: Avg delivery time (min)
A46: 10 | B46: =COUNTIF(Data!$C$2:$C$301,A46) -> 13 | C46: =COUNTIFS(Data!$C$2:$C$301,A46,Data!$F$2:$F$301,"Cancelled") -> 2 | D46: =IFERROR(C46/B46,0) -> 0.15384615 | E46: =IFERROR(AVERAGEIFS(Data!$N$2:$N$301,Data!$C$2:$C$301,A46,Data!$F$2:$F$301,"Delivered"),0) -> 36
A47: 11 | B47: =COUNTIF(Data!$C$2:$C$301,A47) -> 18 | C47: =COUNTIFS(Data!$C$2:$C$301,A47,Data!$F$2:$F$301,"Cancelled") -> 0 | D47: =IFERROR(C47/B47,0) -> 0 | E47: =IFERROR(AVERAGEIFS(Data!$N$2:$N$301,Data!$C$2:$C$301,A47,Data!$F$2:$F$301,"Delivered"),0) -> 34.722222
A48: 12 | B48: =COUNTIF(Data!$C$2:$C$301,A48) -> 27 | C48: =COUNTIFS(Data!$C$2:$C$301,A48,Data!$F$2:$F$301,"Cancelled") -> 7 | D48: =IFERROR(C48/B48,0) -> 0.25925926 | E48: =IFERROR(AVERAGEIFS(Data!$N$2:$N$301,Data!$C$2:$C$301,A48,Data!$F$2:$F$301,"Delivered"),0) -> 49.7
...

Sheet Data
A1: Order ID | B1: Date | C1: Order Hour | D1: Time Band | E1: District | F1: Status | G1: Cancel Reason | H1: Confirmation (min) | I1: Preparation (min) | J1: Courier Assignment (min) | K1: Travel to Restaurant (min) | L1: Wait at Restaurant (min) | M1: Travel to Customer (min) | N1: Total Delivery Time (min) | O1: Rating (1-5) | P1: Item Issue | Q1: SLA Breach
A2: ORD-0001 | B2: 46279 | C2: 11 | D2: =IF(OR(AND(C2>=Assumptions!$B$5,C2<=Assumptions!$B$6),AND(C2>=Assumptions!$B$7,C2<=Assumptions!$B$8)),"Peak","Off-peak") -> Off-peak | E2: Sabail | F2: Delivered | H2: 1 | I2: 14 | J2: 5 | K2: 6 | L2: 2 | M2: 9 | N2: =IF(F2="Delivered",SUM(H2:M2),"") -> 37 | O2: 3 | P2: Missing item | Q2: =IF(F2="Delivered",IF(N2>Assumptions!$B$4,"Yes","No"),"") -> No
A3: ORD-0002 | B3: 46279 | C3: 11 | D3: =IF(OR(AND(C3>=Assumptions!$B$5,C3<=Assumptions!$B$6),AND(C3>=Assumptions!$B$7,C3<=Assumptions!$B$8)),"Peak","Off-peak") -> Off-peak | E3: Nizami | F3: Delivered | H3: 2 | I3: 11 | J3: 3 | K3: 5 | L3: 3 | M3: 8 | N3: =IF(F3="Delivered",SUM(H3:M3),"") -> 32 | O3: 5 | P3: None | Q3: =IF(F3="Delivered",IF(N3>Assumptions!$B$4,"Yes","No"),"") -> No
A4: ORD-0003 | B4: 46279 | C4: 11 | D4: =IF(OR(AND(C4>=Assumptions!$B$5,C4<=Assumptions!$B$6),AND(C4>=Assumptions!$B$7,C4<=Assumptions!$B$8)),"Peak","Off-peak") -> Off-peak | E4: Nizami | F4: Delivered | H4: 2 | I4: 8 | J4: 4 | K4: 5 | L4: 0 | M4: 5 | N4: =IF(F4="Delivered",SUM(H4:M4),"") -> 24 | O4: 4 | P4: Wrong item | Q4: =IF(F4="Delivered",IF(N4>Assumptions!$B$4,"Yes","No"),"") -> No
A5: ORD-0004 | B5: 46279 | C5: 11 | D5: =IF(OR(AND(C5>=Assumptions!$B$5,C5<=Assumptions!$B$6),AND(C5>=Assumptions!$B$7,C5<=Assumptions!$B$8)),"Peak","Off-peak") -> Off-peak | E5: Nasimi | F5: Delivered | H5: 3 | I5: 15 | J5: 2 | K5: 4 | L5: 1 | M5: 21 | N5: =IF(F5="Delivered",SUM(H5:M5),"") -> 46 | O5: 5 | P5: None | Q5: =IF(F5="Delivered",IF(N5>Assumptions!$B$4,"Yes","No"),"") -> Yes
A6: ORD-0005 | B6: 46279 | C6: 12 | D6: =IF(OR(AND(C6>=Assumptions!$B$5,C6<=Assumptions!$B$6),AND(C6>=Assumptions!$B$7,C6<=Assumptions!$B$8)),"Peak","Off-peak") -> Peak | E6: Nizami | F6: Delivered | H6: 3 | I6: 22 | J6: 4 | K6: 9 | L6: 4 | M6: 13 | N6: =IF(F6="Delivered",SUM(H6:M6),"") -> 55 | O6: 3 | P6: None | Q6: =IF(F6="Delivered",IF(N6>Assumptions!$B$4,"Yes","No"),"") -> Yes
A7: ORD-0006 | B7: 46279 | C7: 12 | D7: =IF(OR(AND(C7>=Assumptions!$B$5,C7<=Assumptions!$B$6),AND(C7>=Assumptions!$B$7,C7<=Assumptions!$B$8)),"Peak","Off-peak") -> Peak | E7: Khatai | F7: Delivered | H7: 6 | I7: 10 | J7: 7 | K7: 6 | L7: 3 | M7: 8 | N7: =IF(F7="Delivered",SUM(H7:M7),"") -> 40 | O7: 4 | P7: None | Q7: =IF(F7="Delivered",IF(N7>Assumptions!$B$4,"Yes","No"),"") -> No
A8: ORD-0007 | B8: 46279 | C8: 13 | D8: =IF(OR(AND(C8>=Assumptions!$B$5,C8<=Assumptions!$B$6),AND(C8>=Assumptions!$B$7,C8<=Assumptions!$B$8)),"Peak","Off-peak") -> Peak | E8: Nasimi | F8: Delivered | H8: 3 | I8: 16 | J8: 13 | K8: 2 | L8: 6 | M8: 17 | N8: =IF(F8="Delivered",SUM(H8:M8),"") -> 57 | O8: 4 | P8: None | Q8: =IF(F8="Delivered",IF(N8>Assumptions!$B$4,"Yes","No"),"") -> Yes
A9: ORD-0008 | B9: 46279 | C9: 14 | D9: =IF(OR(AND(C9>=Assumptions!$B$5,C9<=Assumptions!$B$6),AND(C9>=Assumptions!$B$7,C9<=Assumptions!$B$8)),"Peak","Off-peak") -> Off-peak | E9: Yasamal | F9: Delivered | H9: 1 | I9: 7 | J9: 2 | K9: 3 | L9: 1 | M9: 12 | N9: =IF(F9="Delivered",SUM(H9:M9),"") -> 26 | O9: 5 | P9: None | Q9: =IF(F9="Delivered",IF(N9>Assumptions!$B$4,"Yes","No"),"") -> No
A10: ORD-0009 | B10: 46279 | C10: 14 | D10: =IF(OR(AND(C10>=Assumptions!$B$5,C10<=Assumptions!$B$6),AND(C10>=Assumptions!$B$7,C10<=Assumptions!$B$8)),"Peak","Off-peak") -> Off-peak | E10: Sabail | F10: Delivered | H10: 3 | I10: 14 | J10: 3 | K10: 4 | L10: 1 | M10: 10 | N10: =IF(F10="Delivered",SUM(H10:M10),"") -> 35 | O10: 5 | P10: None | Q10: =IF(F10="Delivered",IF(N10>Assumptions!$B$4,"Yes","No"),"") -> No
A11: ORD-0010 | B11: 46279 | C11: 14 | D11: =IF(OR(AND(C11>=Assumptions!$B$5,C11<=Assumptions!$B$6),AND(C11>=Assumptions!$B$7,C11<=Assumptions!$B$8)),"Peak","Off-peak") -> Off-peak | E11: Nizami | F11: Delivered | H11: 1 | I11: 15 | J11: 3 | K11: 3 | L11: 1 | M11: 5 | N11: =IF(F11="Delivered",SUM(H11:M11),"") -> 28 | O11: 4 | P11: Missing item | Q11: =IF(F11="Delivered",IF(N11>Assumptions!$B$4,"Yes","No"),"") -> No
A12: ORD-0011 | B12: 46279 | C12: 14 | D12: =IF(OR(AND(C12>=Assumptions!$B$5,C12<=Assumptions!$B$6),AND(C12>=Assumptions!$B$7,C12<=Assumptions!$B$8)),"Peak","Off-peak") -> Off-peak | E12: Yasamal | F12: Delivered | H12: 3 | I12: 14 | J12: 6 | K12: 8 | L12: 3 | M12: 5 | N12: =IF(F12="Delivered",SUM(H12:M12),"") -> 39 | O12: 4 | P12: None | Q12: =IF(F12="Delivered",IF(N12>Assumptions!$B$4,"Yes","No"),"") -> No
A13: ORD-0012 | B13: 46279 | C13: 14 | D13: =IF(OR(AND(C13>=Assumptions!$B$5,C13<=Assumptions!$B$6),AND(C13>=Assumptions!$B$7,C13<=Assumptions!$B$8)),"Peak","Off-peak") -> Off-peak | E13: Nizami | F13: Delivered | H13: 1 | I13: 11 | J13: 2 | K13: 6 | L13: 1 | M13: 12 | N13: =IF(F13="Delivered",SUM(H13:M13),"") -> 33 | O13: 4 | P13: None | Q13: =IF(F13="Delivered",IF(N13>Assumptions!$B$4,"Yes","No"),"") -> No
... A15: ORD-0014 | B15: 46279 | C15: 17 | D15: =IF(OR(AND(C15>=Assumptions!$B$5,C15<=Assumptions!$B$6),AND(C15>=Assumptions!$B$7,C15<=Assumptions!$B$8)),"Peak","Off-peak") -> Off-peak | E15: Khatai | F15: Delivered | H15: 6 | I15: 13 | J15: 5 | K15: 7 | L15: 3 | M15: 5 | N15: =IF(F15="Delivered",SUM(H15:M15),"") -> 39 | O15: 4 | P15: None | Q15: =IF(F15="Delivered",IF(N15>Assumptions!$B$4,"Yes","No"),"") -> No
A16: ORD-0015 | B16: 46279 | C16: 18 | D16: =IF(OR(AND(C16>=Assumptions!$B$5,C16<=Assumptions!$B$6),AND(C16>=Assumptions!$B$7,C16<=Assumptions!$B$8)),"Peak","Off-peak") -> Off-peak | E16: Sabunchu | F16: Cancelled | G16: Courier not assigned in time | N16: =IF(F16="Delivered",SUM(H16:M16),"") | Q16: =IF(F16="Delivered",IF(N16>Assumptions!$B$4,"Yes","No"),"")
A17: ORD-0016 | B17: 46279 | C17: 18 | D17: =IF(OR(AND(C17>=Assumptions!$B$5,C17<=Assumptions!$B$6),AND(C17>=Assumptions!$B$7,C17<=Assumptions!$B$8)),"Peak","Off-peak") -> Off-peak | E17: Nizami | F17: Delivered | H17: 1 | I17: 15 | J17: 9 | K17: 7 | L17: 1 | M17: 4 | N17: =IF(F17="Delivered",SUM(H17:M17),"") -> 37 | O17: 4 | P17: None | Q17: =IF(F17="Delivered",IF(N17>Assumptions!$B$4,"Yes","No"),"") -> No
A18: ORD-0017 | B18: 46279 | C18: 18 | D18: =IF(OR(AND(C18>=Assumptions!$B$5,C18<=Assumptions!$B$6),AND(C18>=Assumptions!$B$7,C18<=Assumptions!$B$8)),"Peak","Off-peak") -> Off-peak | E18: Binagadi | F18: Delivered | H18: 3 | I18: 16 | J18: 3 | K18: 7 | L18: 4 | M18: 11 | N18: =IF(F18="Delivered",SUM(H18:M18),"") -> 44 | O18: 4 | P18: None | Q18: =IF(F18="Delivered",IF(N18>Assumptions!$B$4,"Yes","No"),"") -> No
A19: ORD-0018 | B19: 46279 | C19: 18 | D19: =IF(OR(AND(C19>=Assumptions!$B$5,C19<=Assumptions!$B$6),AND(C19>=Assumptions!$B$7,C19<=Assumptions!$B$8)),"Peak","Off-peak") -> Off-peak | E19: Khatai | F19: Delivered | H19: 4 | I19: 12 | J19: 5 | K19: 8 | L19: 1 | M19: 6 | N19: =IF(F19="Delivered",SUM(H19:M19),"") -> 36 | O19: 5 | P19: None | Q19: =IF(F19="Delivered",IF(N19>Assumptions!$B$4,"Yes","No"),"") -> No
A20: ORD-0019 | B20: 46279 | C20: 19 | D20: =IF(OR(AND(C20>=Assumptions!$B$5,C20<=Assumptions!$B$6),AND(C20>=Assumptions!$B$7,C20<=Assumptions!$B$8)),"Peak","Off-peak") -> Peak | E20: Sabail | F20: Delivered | H20: 1 | I20: 14 | J20: 10 | K20: 9 | L20: 1 | M20: 7 | N20: =IF(F20="Delivered",SUM(H20:M20),"") -> 42 | O20: 4 | P20: None | Q20: =IF(F20="Delivered",IF(N20>Assumptions!$B$4,"Yes","No"),"") -> No
A21: ORD-0020 | B21: 46279 | C21: 20 | D21: =IF(OR(AND(C21>=Assumptions!$B$5,C21<=Assumptions!$B$6),AND(C21>=Assumptions!$B$7,C21<=Assumptions!$B$8)),"Peak","Off-peak") -> Peak | E21: Yasamal | F21: Delivered | H21: 7 | I21: 13 | J21: 4 | K21: 5 | L21: 6 | M21: 6 | N21: =IF(F21="Delivered",SUM(H21:M21),"") -> 41 | O21: 4 | P21: None | Q21: =IF(F21="Delivered",IF(N21>Assumptions!$B$4,"Yes","No"),"") -> No
A22: ORD-0021 | B22: 46279 | C22: 21 | D22: =IF(OR(AND(C22>=Assumptions!$B$5,C22<=Assumptions!$B$6),AND(C22>=Assumptions!$B$7,C22<=Assumptions!$B$8)),"Peak","Off-peak") -> Peak | E22: Nasimi | F22: Delivered | H22: 9 | I22: 22 | J22: 8 | K22: 8 | L22: 3 | M22: 18 | N22: =IF(F22="Delivered",SUM(H22:M22),"") -> 68 | O22: 4 | P22: None | Q22: =IF(F22="Delivered",IF(N22>Assumptions!$B$4,"Yes","No"),"") -> Yes
A23: ORD-0022 | B23: 46279 | C23: 21 | D23: =IF(OR(AND(C23>=Assumptions!$B$5,C23<=Assumptions!$B$6),AND(C23>=Assumptions!$B$7,C23<=Assumptions!$B$8)),"Peak","Off-peak") -> Peak | E23: Nasimi | F23: Delivered | H23: 5 | I23: 17 | J23: 4 | K23: 13 | L23: 9 | M23: 11 | N23: =IF(F23="Delivered",SUM(H23:M23),"") -> 59 | O23: 4 | P23: None | Q23: =IF(F23="Delivered",IF(N23>Assumptions!$B$4,"Yes","No"),"") -> Yes
A24: ORD-0023 | B24: 46279 | C24: 22 | D24: =IF(OR(AND(C24>=Assumptions!$B$5,C24<=Assumptions!$B$6),AND(C24>=Assumptions!$B$7,C24<=Assumptions!$B$8)),"Peak","Off-peak") -> Off-peak | E24: Khatai | F24: Delivered | H24: 1 | I24: 9 | J24: 6 | K24: 4 | L24: 1 | M24: 5 | N24: =IF(F24="Delivered",SUM(H24:M24),"") -> 26 | O24: 5 | P24: None | Q24: =IF(F24="Delivered",IF(N24>Assumptions!$B$4,"Yes","No"),"") -> No
A25: ORD-0024 | B25: 46279 | C25: 22 | D25: =IF(OR(AND(C25>=Assumptions!$B$5,C25<=Assumptions!$B$6),AND(C25>=Assumptions!$B$7,C25<=Assumptions!$B$8)),"Peak","Off-peak") -> Off-peak | E25: Yasamal | F25: Delivered | H25: 2 | I25: 12 | J25: 4 | K25: 7 | L25: 1 | M25: 6 | N25: =IF(F25="Delivered",SUM(H25:M25),"") -> 32 | O25: 5 | P25: None | Q25: =IF(F25="Delivered",IF(N25>Assumptions!$B$4,"Yes","No"),"") -> No
A26: ORD-0025 | B26: 46279 | C26: 22 | D26: =IF(OR(AND(C26>=Assumptions!$B$5,C26<=Assumptions!$B$6),AND(C26>=Assumptions!$B$7,C26<=Assumptions!$B$8)),"Peak","Off-peak") -> Off-peak | E26: Yasamal | F26: Cancelled | G26: Restaurant did not confirm | N26: =IF(F26="Delivered",SUM(H26:M26),"") | Q26: =IF(F26="Delivered",IF(N26>Assumptions!$B$4,"Yes","No"),"")
A27: ORD-0026 | B27: 46279 | C27: 22 | D27: =IF(OR(AND(C27>=Assumptions!$B$5,C27<=Assumptions!$B$6),AND(C27>=Assumptions!$B$7,C27<=Assumptions!$B$8)),"Peak","Off-peak") -> Off-peak | E27: Binagadi | F27: Delivered | H27: 3 | I27: 13 | J27: 4 | K27: 9 | L27: 2 | M27: 16 | N27: =IF(F27="Delivered",SUM(H27:M27),"") -> 47 | O27: 3 | P27: None | Q27: =IF(F27="Delivered",IF(N27>Assumptions!$B$4,"Yes","No"),"") -> Yes
A28: ORD-0027 | B28: 46280 | C28: 10 | D28: =IF(OR(AND(C28>=Assumptions!$B$5,C28<=Assumptions!$B$6),AND(C28>=Assumptions!$B$7,C28<=Assumptions!$B$8)),"Peak","Off-peak") -> Off-peak | E28: Khatai | F28: Delivered | H28: 1 | I28: 10 | J28: 3 | K28: 5 | L28: 3 | M28: 10 | N28: =IF(F28="Delivered",SUM(H28:M28),"") -> 32 | O28: 5 | P28: None | Q28: =IF(F28="Delivered",IF(N28>Assumptions!$B$4,"Yes","No"),"") -> No
A29: ORD-0028 | B29: 46280 | C29: 10 | D29: =IF(OR(AND(C29>=Assumptions!$B$5,C29<=Assumptions!$B$6),AND(C29>=Assumptions!$B$7,C29<=Assumptions!$B$8)),"Peak","Off-peak") -> Off-peak | E29: Sabunchu | F29: Delivered | H29: 1 | I29: 4 | J29: 2 | K29: 16 | L29: 0 | M29: 14 | N29: =IF(F29="Delivered",SUM(H29:M29),"") -> 37 | O29: 5 | P29: None | Q29: =IF(F29="Delivered",IF(N29>Assumptions!$B$4,"Yes","No"),"") -> No
A30: ORD-0029 | B30: 46280 | C30: 10 | D30: =IF(OR(AND(C30>=Assumptions!$B$5,C30<=Assumptions!$B$6),AND(C30>=Assumptions!$B$7,C30<=Assumptions!$B$8)),"Peak","Off-peak") -> Off-peak | E30: Binagadi | F30: Delivered | H30: 2 | I30: 13 | J30: 2 | K30: 11 | L30: 1 | M30: 11 | N30: =IF(F30="Delivered",SUM(H30:M30),"") -> 40 | O30: 4 | P30: None | Q30: =IF(F30="Delivered",IF(N30>Assumptions!$B$4,"Yes","No"),"") -> No
A31: ORD-0030 | B31: 46280 | C31: 11 | D31: =IF(OR(AND(C31>=Assumptions!$B$5,C31<=Assumptions!$B$6),AND(C31>=Assumptions!$B$7,C31<=Assumptions!$B$8)),"Peak","Off-peak") -> Off-peak | E31: Nizami | F31: Delivered | H31: 4 | I31: 12 | J31: 2 | K31: 10 | L31: 2 | M31: 6 | N31: =IF(F31="Delivered",SUM(H31:M31),"") -> 36 | O31: 5 | P31: None | Q31: =IF(F31="Delivered",IF(N31>Assumptions!$B$4,"Yes","No"),"") -> No
A32: ORD-0031 | B32: 46280 | C32: 12 | D32: =IF(OR(AND(C32>=Assumptions!$B$5,C32<=Assumptions!$B$6),AND(C32>=Assumptions!$B$7,C32<=Assumptions!$B$8)),"Peak","Off-peak") -> Peak | E32: Nasimi | F32: Delivered | H32: 4 | I32: 19 | J32: 7 | K32: 5 | L32: 7 | M32: 6 | N32: =IF(F32="Delivered",SUM(H32:M32),"") -> 48 | O32: 4 | P32: None | Q32: =IF(F32="Delivered",IF(N32>Assumptions!$B$4,"Yes","No"),"") -> Yes
A33: ORD-0032 | B33: 46280 | C33: 12 | D33: =IF(OR(AND(C33>=Assumptions!$B$5,C33<=Assumptions!$B$6),AND(C33>=Assumptions!$B$7,C33<=Assumptions!$B$8)),"Peak","Off-peak") -> Peak | E33: Nizami | F33: Cancelled | G33: Customer cancelled: long wait | N33: =IF(F33="Delivered",SUM(H33:M33),"") | Q33: =IF(F33="Delivered",IF(N33>Assumptions!$B$4,"Yes","No"),"")
A34: ORD-0033 | B34: 46280 | C34: 13 | D34: =IF(OR(AND(C34>=Assumptions!$B$5,C34<=Assumptions!$B$6),AND(C34>=Assumptions!$B$7,C34<=Assumptions!$B$8)),"Peak","Off-peak") -> Peak | E34: Sabunchu | F34: Delivered | H34: 5 | I34: 21 | J34: 5 | K34: 14 | L34: 3 | M34: 5 | N34: =IF(F34="Delivered",SUM(H34:M34),"") -> 53 | O34: 4 | P34: None | Q34: =IF(F34="Delivered",IF(N34>Assumptions!$B$4,"Yes","No"),"") -> Yes
A35: ORD-0034 | B35: 46280 | C35: 15 | D35: =IF(OR(AND(C35>=Assumptions!$B$5,C35<=Assumptions!$B$6),AND(C35>=Assumptions!$B$7,C35<=Assumptions!$B$8)),"Peak","Off-peak") -> Off-peak | E35: Sabunchu | F35: Delivered | H35: 1 | I35: 6 | J35: 3 | K35: 6 | L35: 2 | M35: 10 | N35: =IF(F35="Delivered",SUM(H35:M35),"") -> 28 | O35: 5 | P35: None | Q35: =IF(F35="Delivered",IF(N35>Assumptions!$B$4,"Yes","No"),"") -> No
A36: ORD-0035 | B36: 46280 | C36: 17 | D36: =IF(OR(AND(C36>=Assumptions!$B$5,C36<=Assumptions!$B$6),AND(C36>=Assumptions!$B$7,C36<=Assumptions!$B$8)),"Peak","Off-peak") -> Off-peak | E36: Sabunchu | F36: Delivered | H36: 1 | I36: 15 | J36: 1 | K36: 11 | L36: 1 | M36: 14 | N36: =IF(F36="Delivered",SUM(H36:M36),"") -> 43 | O36: 4 | P36: None | Q36: =IF(F36="Delivered",IF(N36>Assumptions!$B$4,"Yes","No"),"") -> No
A37: ORD-0036 | B37: 46280 | C37: 21 | D37: =IF(OR(AND(C37>=Assumptions!$B$5,C37<=Assumptions!$B$6),AND(C37>=Assumptions!$B$7,C37<=Assumptions!$B$8)),"Peak","Off-peak") -> Peak | E37: Sabail | F37: Delivered | H37: 2 | I37: 12 | J37: 6 | K37: 7 | L37: 2 | M37: 6 | N37: =IF(F37="Delivered",SUM(H37:M37),"") -> 35 | O37: 4 | P37: None | Q37: =IF(F37="Delivered",IF(N37>Assumptions!$B$4,"Yes","No"),"") -> No
A38: ORD-0037 | B38: 46280 | C38: 21 | D38: =IF(OR(AND(C38>=Assumptions!$B$5,C38<=Assumptions!$B$6),AND(C38>=Assumptions!$B$7,C38<=Assumptions!$B$8)),"Peak","Off-peak") -> Peak | E38: Binagadi | F38: Delivered | H38: 4 | I38: 14 | J38: 9 | K38: 5 | L38: 3 | M38: 20 | N38: =IF(F38="Delivered",SUM(H38:M38),"") -> 55 | O38: 4 | P38: None | Q38: =IF(F38="Delivered",IF(N38>Assumptions!$B$4,"Yes","No"),"") -> Yes
A39: ORD-0038 | B39: 46280 | C39: 21 | D39: =IF(OR(AND(C39>=Assumptions!$B$5,C39<=Assumptions!$B$6),AND(C39>=Assumptions!$B$7,C39<=Assumptions!$B$8)),"Peak","Off-peak") -> Peak | E39: Binagadi | F39: Delivered | H39: 4 | I39: 15 | J39: 9 | K39: 12 | L39: 1 | M39: 23 | N39: =IF(F39="Delivered",SUM(H39:M39),"") -> 64 | O39: 3 | P39: None | Q39: =IF(F39="Delivered",IF(N39>Assumptions!$B$4,"Yes","No"),"") -> Yes
A40: ORD-0039 | B40: 46280 | C40: 22 | D40: =IF(OR(AND(C40>=Assumptions!$B$5,C40<=Assumptions!$B$6),AND(C40>=Assumptions!$B$7,C40<=Assumptions!$B$8)),"Peak","Off-peak") -> Off-peak | E40: Binagadi | F40: Delivered | H40: 1 | I40: 10 | J40: 7 | K40: 9 | L40: 1 | M40: 12 | N40: =IF(F40="Delivered",SUM(H40:M40),"") -> 40 | O40: 4 | P40: None | Q40: =IF(F40="Delivered",IF(N40>Assumptions!$B$4,"Yes","No"),"") -> No
A41: ORD-0040 | B41: 46280 | C41: 22 | D41: =IF(OR(AND(C41>=Assumptions!$B$5,C41<=Assumptions!$B$6),AND(C41>=Assumptions!$B$7,C41<=Assumptions!$B$8)),"Peak","Off-peak") -> Off-peak | E41: Nasimi | F41: Delivered | H41: 2 | I41: 12 | J41: 3 | K41: 5 | L41: 2 | M41: 13 | N41: =IF(F41="Delivered",SUM(H41:M41),"") -> 37 | O41: 4 | P41: None | Q41: =IF(F41="Delivered",IF(N41>Assumptions!$B$4,"Yes","No"),"") -> No
...

Sheet Assumptions
A1: Assumptions and Notes
A2: Blue cells are inputs. Change them and the Data and Dashboard sheets recalculate.
A3: Parameter | B3: Value | C3: Source / note
A4: SLA threshold (min) | B4: 45 | C4: Assumption: a delivery longer than this counts as an SLA breach
A5: Lunch peak starts (hour) | B5: 12 | C5: business-case.md: peak 12:00-14:00
A6: Lunch peak last hour | B6: 13 | C6: Orders placed from 12:00 to 13:59
A7: Dinner peak starts (hour) | B7: 19 | C7: business-case.md: peak 19:00-22:00
A8: Dinner peak last hour | B8: 21 | C8: Orders placed from 19:00 to 21:59
A9: Target avg delivery time (min) | B9: 34 | C9: Goal G1 in business-case.md
A10: Target cancellation rate | B10: 0.07 | C10: Goal G2 in business-case.md
A11: Target avg customer rating | B11: 4.4 | C11: Goal G3 in business-case.md
A12: Business case baseline: avg delivery time (min) | B12: 41 | C12: Problem statement in business-case.md
A13: Business case baseline: cancellation rate | B13: 0.11 | C13: Problem statement in business-case.md
A14: Business case baseline: avg customer rating | B14: 4.1 | C14: Goal G3 baseline in business-case.md
A17: About the data
A18: All data on the Data sheet is synthetic (randomly generated with a fixed seed) and created for demonstration only.
A19: 300 orders over 14 days (14-27 Sep 2026) for the fictional platform FoodGo in Baku.
A20: The data was calibrated so that the totals match the business case baseline: about 41 min delivery time, 11% cancellations, 4.1 rating.
A21: Delivery time is the sum of six process stages, in the AS-IS order: confirmation, preparation, courier assignment, travel to restaurant, wait at restaurant, travel to customer.
A22: Cancelled orders have no stage times, rating or item issue (cells are empty).
